<?xml version="1.0"?>
<robot xmlns:xacro="http://ros.org/wiki/xacro" name="big_arm">

  <!-- BIG ARM -->
  <xacro:macro name="big_arm" params=" parent:='' *origin ">

  <link name="big_arm_link_0"/>

  <link name="big_arm_link_1">
    <visual>
      <geometry>
        <mesh filename="package://gateway_description/meshes/big_arm/big_arm_link_1.dae" scale="1.0 1.0 1.0"/>
      </geometry>
    </visual>
    <collision> 
      <geometry>
        <mesh filename="package://gateway_description/meshes/big_arm/big_arm_link_1.dae" scale="1.0 1.0 1.0"/>
      </geometry>
    </collision>
    <inertial>
      <origin rpy="0 -1.5708 0" xyz="0.25082 0 -0.175"/>
      <mass value="105.98"/>
      <inertia ixx="12.19" ixy="0" ixz="0" iyy="12.19" iyz="0" izz="3.061"/>
    </inertial>  
  </link>

  <link name="big_arm_link_2">
    <visual>
      <geometry>
        <mesh filename="package://gateway_description/meshes/big_arm/big_arm_link_2.dae" scale="1.0 1.0 1.0"/>
      </geometry>
    </visual>
    <collision> 
      <geometry>
        <mesh filename="package://gateway_description/meshes/big_arm/big_arm_link_2.dae" scale="1.0 1.0 1.0"/>
      </geometry>
    </collision>
    <inertial>
      <origin rpy="0 0 0" xyz="0.175 0 -0.25082"/>
      <mass value="105.98"/>
      <inertia ixx="12.19" ixy="0" ixz="0" iyy="12.13" iyz="0" izz="3.061"/>
    </inertial>    
  </link>

  <link name="big_arm_link_3">
    <visual>
      <geometry>
        <mesh filename="package://gateway_description/meshes/big_arm/big_arm_link_3.dae" scale="1.0 1.0 1.0"/>
      </geometry>
    </visual>
    <collision> 
      <geometry>
        <mesh filename="package://gateway_description/meshes/big_arm/big_arm_link_3.dae" scale="1.0 1.0 1.0"/>
      </geometry>
    </collision>
    <inertial>
      <origin rpy="3.14 0 0" xyz="4.0 0 -0.175"/>
      <mass value="314.88"/>
      <inertia ixx="15.41" ixy="0" ixz="0" iyy="2094.71" iyz="0" izz="2103.19"/>
    </inertial>      
  </link>

  <link name="big_arm_link_4">
    <visual>
      <geometry>
        <mesh filename="package://gateway_description/meshes/big_arm/big_arm_link_4.dae" scale="1.0 1.0 1.0"/>
      </geometry>
    </visual>
    <collision> 
      <geometry>
        <mesh filename="package://gateway_description/meshes/big_arm/big_arm_link_4.dae" scale="1.0 1.0 1.0"/>
      </geometry>
    </collision>
    <inertial>
      <origin rpy="0 0 0" xyz="-3.6 0 -0.175"/>
      <mass value="279.2"/>
      <inertia ixx="9.522" ixy="0" ixz="0" iyy="1966.28" iyz="0" izz="1966.28"/>
    </inertial>        
  </link>

  <link name="big_arm_link_5">
    <visual>
      <geometry>
        <mesh filename="package://gateway_description/meshes/big_arm/big_arm_link_5.dae" scale="1.0 1.0 1.0"/>
      </geometry>
    </visual>
    <collision> 
      <geometry>
        <mesh filename="package://gateway_description/meshes/big_arm/big_arm_link_5.dae" scale="1.0 1.0 1.0"/>
      </geometry>
    </collision>
    <inertial>
      <origin rpy="1.5708 0 0" xyz="0 0 0.0"/>
      <mass value="105.98"/>
      <inertia ixx="8.305" ixy="0" ixz="0" iyy="3.061" iyz="0" izz="8.0386"/>
    </inertial>       
  </link>


  <link name="big_arm_link_6">
    <visual>
      <geometry>
        <mesh filename="package://gateway_description/meshes/big_arm/big_arm_link_6.dae" scale="1.0 1.0 1.0"/>
      </geometry>
    </visual>
    <collision> 
      <geometry>
        <mesh filename="package://gateway_description/meshes/big_arm/big_arm_link_6.dae" scale="1.0 1.0 1.0"/>
      </geometry>
    </collision>
    <inertial>
      <origin rpy="0 -1.5708 0" xyz="0 0 0"/>
      <mass value="105.98"/>
      <inertia ixx="12.13" ixy="0" ixz="0" iyy="12.13" iyz="0" izz="3.061"/>
    </inertial>     
  </link>


  <link name="big_arm_link_7">
    <visual>
      <geometry>
        <mesh filename="package://gateway_description/meshes/big_arm/big_arm_link_7.dae" scale="1.0 1.0 1.0"/>
      </geometry>
    </visual>
    <collision> 
      <geometry>
        <mesh filename="package://gateway_description/meshes/big_arm/big_arm_link_7.dae" scale="1.0 1.0 1.0"/>
      </geometry>
    </collision>
    <inertial>
      <origin rpy="0 1.5708 0" xyz="0 0 -0.5"/>
      <mass value="243.66"/>
      <inertia ixx="9.336" ixy="0" ixz="0" iyy="44.41" iyz="0" izz="44.41"/>
    </inertial>      
  </link>


  <link name="big_arm_link_8">
    <visual>
      <geometry>
        <mesh filename="package://gateway_description/meshes/big_arm/big_arm_link_8.dae" scale="1.0 1.0 1.0"/>
      </geometry>
    </visual>
    <collision> 
      <geometry>
        <mesh filename="package://gateway_description/meshes/big_arm/big_arm_link_8.dae" scale="1.0 1.0 1.0"/>
      </geometry>
    </collision>
    <inertial>
      <origin rpy="0 1.5708 0" xyz="0 0 -0.5"/>
      <mass value="243.66"/>
      <inertia ixx="9.336" ixy="0" ixz="0" iyy="44.41" iyz="0" izz="44.41"/>
    </inertial>    
  </link>

  <joint name="big_arm_joint_0" type="fixed">
    <parent link="${parent}"/>
    <child link="big_arm_link_0"/>
    <xacro:insert_block name="origin"/>
  </joint>
  
  <joint name="big_arm_joint_1" type="fixed">
    <parent link="big_arm_link_0"/>
    <child link="big_arm_link_1"/>
    <origin xyz="3.7698 0.3139 1.6058" rpy="0.0 -0.2094 -1.5708"/>
  </joint>

  <joint name="big_arm_joint_2" type="revolute">
    <parent link="big_arm_link_1"/>
    <child link="big_arm_link_2"/>
    <axis xyz="0 0 1"/>
    <limit lower="-3.14" upper="3.14" velocity="3.1416" effort="100"/> <!-- MADE UP NUMBERS JUST FOR TESTING -->
    <origin xyz="0.0 0.0 0.4409" rpy="0.0 0.0 0.8726648"/>
  </joint>

  <joint name="big_arm_joint_3" type="revolute">
    <parent link="big_arm_link_2"/>
    <child link="big_arm_link_3"/>
    <origin xyz="0.0 -0.177 0.1515" rpy="2.98023e-8 0.0  1.862645e-8"/>
    <axis xyz="0 1 0"/>
    <limit lower="-3.14" upper="3.14" velocity="3.1416" effort="100"/> <!-- MADE UP NUMBERS JUST FOR TESTING -->
  </joint>


  <joint name="big_arm_joint_4" type="revolute">
    <parent link="big_arm_link_3"/>
    <child link="big_arm_link_4"/>
    <origin xyz="0.17432 -0.1594 0.0" rpy="0.95993114 0.0 0.0"/>
    <axis xyz="1 0 0"/>
    <limit lower="-3.14" upper="3.14" velocity="3.1416" effort="100"/> <!-- MADE UP NUMBERS JUST FOR TESTING -->
  </joint>


  <joint name="big_arm_joint_5" type="revolute">
    <parent link="big_arm_link_4"/>
    <child link="big_arm_link_5"/>
    <origin xyz="0.3503 -0.004789 3.6578" rpy="1.3089968 0.0 0.0"/>
    <axis xyz="1 0 0"/>
    <limit lower="-3.14" upper="3.14" velocity="3.1416" effort="100"/> <!-- MADE UP NUMBERS JUST FOR TESTING -->
  </joint>


  <joint name="big_arm_joint_6" type="revolute">
    <parent link="big_arm_link_5"/>
    <child link="big_arm_link_6"/>
    <origin xyz="0.3503 0.004781 -3.6578" rpy="-0.5235989 0.0 0.0"/>
    <axis xyz="1 0 0"/>
    <limit lower="-3.14" upper="3.14" velocity="3.1416" effort="100"/> <!-- MADE UP NUMBERS JUST FOR TESTING -->
  </joint>


  <joint name="big_arm_joint_7" type="revolute">
    <parent link="big_arm_link_6"/>
    <child link="big_arm_link_7"/>
    <origin xyz="0.17429 -0.15194 0.0" rpy="0.0 0.0 0.0"/>
    <axis xyz="0 1 0"/>
    <limit lower="-3.14" upper="3.14" velocity="3.1416" effort="100"/> <!-- MADE UP NUMBERS JUST FOR TESTING -->
  </joint>


  <joint name="big_arm_joint_8" type="revolute">
    <parent link="big_arm_link_7"/>
    <child link="big_arm_link_8"/>
    <origin xyz="-0.004217 -0.1708 -0.181" rpy="0.0 0.0 0.0"/>
    <axis xyz="0 0 1"/>
    <limit lower="-3.14" upper="3.14" velocity="3.1416" effort="100"/> <!-- MADE UP NUMBERS JUST FOR TESTING -->
  </joint>

  </xacro:macro>

</robot>
