<?xml version="1.0"?>
<robot xmlns:xacro="http://ros.org/wiki/xacro" name="big_arm">

  <!-- BIG ARM -->
  <xacro:macro name="big_arm" params=" *origin "> <!-- parent:=''-->

  <link name="big_arm_link_0"/>

  <link name="big_arm_link_1">
    <visual>
      <geometry>
        <mesh filename="package://gateway_description/meshes/big_arm/big_arm_link_1.dae" scale="1.0 1.0 1.0"/>
      </geometry>
    </visual>
    <collision> 
      <geometry>
        <mesh filename="package://gateway_description/meshes/big_arm/big_arm_link_1.dae" scale="1.0 1.0 1.0"/>
      </geometry>
    </collision>    
  </link>

  <link name="big_arm_link_2">
    <visual>
      <geometry>
        <mesh filename="package://gateway_description/meshes/big_arm/big_arm_link_2.dae" scale="1.0 1.0 1.0"/>
      </geometry>
    </visual>
    <collision> 
      <geometry>
        <mesh filename="package://gateway_description/meshes/big_arm/big_arm_link_2.dae" scale="1.0 1.0 1.0"/>
      </geometry>
    </collision>    
  </link>

  <link name="big_arm_link_3">
    <visual>
      <geometry>
        <mesh filename="package://gateway_description/meshes/big_arm/big_arm_link_3.dae" scale="1.0 1.0 1.0"/>
      </geometry>
    </visual>
    <collision> 
      <geometry>
        <mesh filename="package://gateway_description/meshes/big_arm/big_arm_link_3.dae" scale="1.0 1.0 1.0"/>
      </geometry>
    </collision>    
  </link>

  <link name="big_arm_link_4">
    <visual>
      <geometry>
        <mesh filename="package://gateway_description/meshes/big_arm/big_arm_link_4.dae" scale="1.0 1.0 1.0"/>
      </geometry>
    </visual>
    <collision> 
      <geometry>
        <mesh filename="package://gateway_description/meshes/big_arm/big_arm_link_4.dae" scale="1.0 1.0 1.0"/>
      </geometry>
    </collision>    
  </link>

  <link name="big_arm_link_5">
    <visual>
      <geometry>
        <mesh filename="package://gateway_description/meshes/big_arm/big_arm_link_5.dae" scale="1.0 1.0 1.0"/>
      </geometry>
    </visual>
    <collision> 
      <geometry>
        <mesh filename="package://gateway_description/meshes/big_arm/big_arm_link_5.dae" scale="1.0 1.0 1.0"/>
      </geometry>
    </collision>    
  </link>


  <link name="big_arm_link_6">
    <visual>
      <geometry>
        <mesh filename="package://gateway_description/meshes/big_arm/big_arm_link_6.dae" scale="1.0 1.0 1.0"/>
      </geometry>
    </visual>
    <collision> 
      <geometry>
        <mesh filename="package://gateway_description/meshes/big_arm/big_arm_link_6.dae" scale="1.0 1.0 1.0"/>
      </geometry>
    </collision>    
  </link>


  <link name="big_arm_link_7">
    <visual>
      <geometry>
        <mesh filename="package://gateway_description/meshes/big_arm/big_arm_link_7.dae" scale="1.0 1.0 1.0"/>
      </geometry>
    </visual>
    <collision> 
      <geometry>
        <mesh filename="package://gateway_description/meshes/big_arm/big_arm_link_7.dae" scale="1.0 1.0 1.0"/>
      </geometry>
    </collision>    
  </link>


  <link name="big_arm_link_8">
    <visual>
      <geometry>
        <mesh filename="package://gateway_description/meshes/big_arm/big_arm_link_8.dae" scale="1.0 1.0 1.0"/>
      </geometry>
    </visual>
    <collision> 
      <geometry>
        <mesh filename="package://gateway_description/meshes/big_arm/big_arm_link_8.dae" scale="1.0 1.0 1.0"/>
      </geometry>
    </collision>    
  </link>

  <!-- <joint name="big_arm_joint_0" type="fixed">
    <parent link="${parent}"/>
    <child link="big_arm_link_0"/>
    <xacro:insert_block name="origin"/>
  </joint> -->
  
  <joint name="big_arm_joint_1" type="fixed">
    <parent link="big_arm_link_0"/>
    <child link="big_arm_link_1"/>
    <origin xyz="3.7698 0.3139 1.6058" rpy="0.0 -0.2094 -1.5708"/>
  </joint>

  <joint name="big_arm_joint_2" type="revolute">
    <parent link="big_arm_link_1"/>
    <child link="big_arm_link_2"/>
    <axis xyz="0 0 1"/>
    <limit lower="-3.14" upper="3.14" velocity="3.1416" effort="100"/> <!-- MADE UP NUMBERS JUST FOR TESTING -->
    <origin xyz="0.0 0.0 0.4409" rpy="0.0 0.0 0.8726648"/>
  </joint>

  <joint name="big_arm_joint_3" type="revolute">
    <parent link="big_arm_link_2"/>
    <child link="big_arm_link_3"/>
    <origin xyz="0.0 -0.177 0.1515" rpy="2.98023e-8 0.0  1.862645e-8"/>
    <axis xyz="0 1 0"/>
    <limit lower="-3.14" upper="3.14" velocity="3.1416" effort="100"/> <!-- MADE UP NUMBERS JUST FOR TESTING -->
  </joint>


  <joint name="big_arm_joint_4" type="revolute">
    <parent link="big_arm_link_3"/>
    <child link="big_arm_link_4"/>
    <origin xyz="0.17432 -0.1594 0.0" rpy="0.95993114 0.0 0.0"/>
    <axis xyz="1 0 0"/>
    <limit lower="-3.14" upper="3.14" velocity="3.1416" effort="100"/> <!-- MADE UP NUMBERS JUST FOR TESTING -->
  </joint>


  <joint name="big_arm_joint_5" type="revolute">
    <parent link="big_arm_link_4"/>
    <child link="big_arm_link_5"/>
    <origin xyz="0.3503 -0.004789 3.6578" rpy="1.3089968 0.0 0.0"/>
    <axis xyz="1 0 0"/>
    <limit lower="-3.14" upper="3.14" velocity="3.1416" effort="100"/> <!-- MADE UP NUMBERS JUST FOR TESTING -->
  </joint>


  <joint name="big_arm_joint_6" type="revolute">
    <parent link="big_arm_link_5"/>
    <child link="big_arm_link_6"/>
    <origin xyz="0.3503 0.004781 -3.6578" rpy="-0.5235989 0.0 0.0"/>
    <axis xyz="1 0 0"/>
    <limit lower="-3.14" upper="3.14" velocity="3.1416" effort="100"/> <!-- MADE UP NUMBERS JUST FOR TESTING -->
  </joint>


  <joint name="big_arm_joint_7" type="revolute">
    <parent link="big_arm_link_6"/>
    <child link="big_arm_link_7"/>
    <origin xyz="0.17429 -0.15194 0.0" rpy="0.0 0.0 0.0"/>
    <axis xyz="0 1 0"/>
    <limit lower="-3.14" upper="3.14" velocity="3.1416" effort="100"/> <!-- MADE UP NUMBERS JUST FOR TESTING -->
  </joint>


  <joint name="big_arm_joint_8" type="revolute">
    <parent link="big_arm_link_7"/>
    <child link="big_arm_link_8"/>
    <origin xyz="-0.004217 -0.1708 -0.181" rpy="0.0 0.0 0.0"/>
    <axis xyz="0 0 1"/>
    <limit lower="-3.14" upper="3.14" velocity="3.1416" effort="100"/> <!-- MADE UP NUMBERS JUST FOR TESTING -->
  </joint>

  </xacro:macro>

</robot>
