<?xml version="1.0"?>
<robot xmlns:xacro="http://ros.org/wiki/xacro" name="gateway">
  
  <link name="root"/>
<!--  <link name="mover"/>-->
  

  <link name="airlock">
    <visual>
      <geometry>
        <mesh filename="package://gateway_description/meshes/airlock/airlock.dae" scale="1.0 1.0 1.0"/>
      </geometry>
    </visual>
    <collision> 
      <geometry>
        <mesh filename="package://gateway_description/meshes/airlock/airlock.dae" scale="1.0 1.0 1.0"/>
      </geometry>
    </collision>    
  </link>


  <link name="ihab">
    <visual>
      <geometry>
        <mesh filename="package://gateway_description/meshes/ihab/ihab.dae" scale="1.0 1.0 1.0"/>
      </geometry>
    </visual>
    <collision> 
      <geometry>
        <mesh filename="package://gateway_description/meshes/ihab/ihab.dae" scale="1.0 1.0 1.0"/>
      </geometry>
    </collision>    
  </link>

  <link name="ng_halo">
    <visual>
      <geometry>
        <mesh filename="package://gateway_description/meshes/ng_halo/ng_halo.dae" scale="1.0 1.0 1.0"/>
      </geometry>
    </visual>
    <collision> 
      <geometry>
        <mesh filename="package://gateway_description/meshes/ng_halo/ng_halo.dae" scale="1.0 1.0 1.0"/>
      </geometry>
    </collision>    
  </link>

  <link name="ermxl">
    <visual>
      <geometry>
        <mesh filename="package://gateway_description/meshes/ermxl/ermxl.dae" scale="1.0 1.0 1.0"/>
      </geometry>
    </visual>
    <collision> 
      <geometry>
        <mesh filename="package://gateway_description/meshes/ermxl/ermxl.dae" scale="1.0 1.0 1.0"/>
      </geometry>
    </collision>    
  </link>

  <link name="maxar_ppe">
    <visual>
      <geometry>
        <mesh filename="package://gateway_description/meshes/maxar_ppe/maxar_ppe.dae" scale="1.0 1.0 1.0"/>
      </geometry>
    </visual>
    <collision> 
      <geometry>
        <mesh filename="package://gateway_description/meshes/maxar_ppe/maxar_ppe.dae" scale="1.0 1.0 1.0"/>
      </geometry>
    </collision>    
  </link>



<!--  <joint name="joint_root_mover" type="fixed">
    <parent link="root"/>
    <child link="mover"/>
    <origin xyz="0.0 0.0 0.0" rpy="-0.1454025 -0.4132539 -1.3967219"/>
  </joint>
-->

  <joint name="joint_root_airlock" type="fixed">
    <parent link="root"/>
    <child link="airlock"/>
    <origin xyz="0.0 0.0 0.0" rpy="0.0 0.0 0.0"/>
  </joint>

  <joint name="joint_root_ihab" type="fixed">
    <parent link="root"/>
    <child link="ihab"/>
    <origin xyz="0.0 0.0 0.0" rpy="0.0 0.0 0.0"/>
  </joint>

  <joint name="joint_root_ng_halo" type="fixed">
    <parent link="root"/>
    <child link="ng_halo"/>
    <origin xyz="0.0 0.0 0.0" rpy="0.0 0.0 0.0"/>
  </joint>

  <joint name="joint_root_ermxl" type="fixed">
    <parent link="root"/>
    <child link="ermxl"/>
    <origin xyz="0.0 0.0 0.0" rpy="0.0 0.0 0.0"/>
  </joint>

  <joint name="joint_root_maxar_ppe" type="fixed">
    <parent link="root"/>
    <child link="maxar_ppe"/>
    <origin xyz="0.0 0.0 0.0" rpy="0.0 0.0 0.0"/>
  </joint>

  <!-- BIG ARM -->
  <link name="big_arm_link_0"/>

  <link name="big_arm_link_1">
    <visual>
      <geometry>
        <mesh filename="package://gateway_description/meshes/big_arm/big_arm_link_1.dae" scale="1.0 1.0 1.0"/>
      </geometry>
    </visual>
    <collision> 
      <geometry>
        <mesh filename="package://gateway_description/meshes/big_arm/big_arm_link_1.dae" scale="1.0 1.0 1.0"/>
      </geometry>
    </collision>    
  </link>

  <link name="big_arm_link_2">
    <visual>
      <geometry>
        <mesh filename="package://gateway_description/meshes/big_arm/big_arm_link_2.dae" scale="1.0 1.0 1.0"/>
      </geometry>
    </visual>
    <collision> 
      <geometry>
        <mesh filename="package://gateway_description/meshes/big_arm/big_arm_link_2.dae" scale="1.0 1.0 1.0"/>
      </geometry>
    </collision>    
  </link>

  <link name="big_arm_link_3">
    <visual>
      <geometry>
        <mesh filename="package://gateway_description/meshes/big_arm/big_arm_link_3.dae" scale="1.0 1.0 1.0"/>
      </geometry>
    </visual>
    <collision> 
      <geometry>
        <mesh filename="package://gateway_description/meshes/big_arm/big_arm_link_3.dae" scale="1.0 1.0 1.0"/>
      </geometry>
    </collision>    
  </link>

  <link name="big_arm_link_4">
    <visual>
      <geometry>
        <mesh filename="package://gateway_description/meshes/big_arm/big_arm_link_4.dae" scale="1.0 1.0 1.0"/>
      </geometry>
    </visual>
    <collision> 
      <geometry>
        <mesh filename="package://gateway_description/meshes/big_arm/big_arm_link_4.dae" scale="1.0 1.0 1.0"/>
      </geometry>
    </collision>    
  </link>

  <link name="big_arm_link_5">
    <visual>
      <geometry>
        <mesh filename="package://gateway_description/meshes/big_arm/big_arm_link_5.dae" scale="1.0 1.0 1.0"/>
      </geometry>
    </visual>
    <collision> 
      <geometry>
        <mesh filename="package://gateway_description/meshes/big_arm/big_arm_link_5.dae" scale="1.0 1.0 1.0"/>
      </geometry>
    </collision>    
  </link>


  <link name="big_arm_link_6">
    <visual>
      <geometry>
        <mesh filename="package://gateway_description/meshes/big_arm/big_arm_link_6.dae" scale="1.0 1.0 1.0"/>
      </geometry>
    </visual>
    <collision> 
      <geometry>
        <mesh filename="package://gateway_description/meshes/big_arm/big_arm_link_6.dae" scale="1.0 1.0 1.0"/>
      </geometry>
    </collision>    
  </link>


  <link name="big_arm_link_7">
    <visual>
      <geometry>
        <mesh filename="package://gateway_description/meshes/big_arm/big_arm_link_7.dae" scale="1.0 1.0 1.0"/>
      </geometry>
    </visual>
    <collision> 
      <geometry>
        <mesh filename="package://gateway_description/meshes/big_arm/big_arm_link_7.dae" scale="1.0 1.0 1.0"/>
      </geometry>
    </collision>    
  </link>


  <link name="big_arm_link_8">
    <visual>
      <geometry>
        <mesh filename="package://gateway_description/meshes/big_arm/big_arm_link_8.dae" scale="1.0 1.0 1.0"/>
      </geometry>
    </visual>
    <collision> 
      <geometry>
        <mesh filename="package://gateway_description/meshes/big_arm/big_arm_link_8.dae" scale="1.0 1.0 1.0"/>
      </geometry>
    </collision>    
  </link>

  <joint name="big_arm_joint_0" type="fixed">
    <parent link="root"/>
    <child link="big_arm_link_0"/>
    <origin xyz="0.0 0.0 0.0" rpy="0.0 0.4363 -1.396"/>
  </joint>
  
  <joint name="big_arm_joint_1" type="fixed">
    <parent link="big_arm_link_0"/>
    <child link="big_arm_link_1"/>
    <origin xyz="3.7698 0.3139 1.6058" rpy="0.0 -0.2094 -1.5708"/>
  </joint>

  <joint name="big_arm_joint_2" type="revolute">
    <parent link="big_arm_link_1"/>
    <child link="big_arm_link_2"/>
    <axis xyz="0 0 1"/>
    <limit lower="-1.5708" upper="1.5708" velocity="3.1416" effort="100"/> <!-- MADE UP NUMBERS JUST FOR TESTING -->
    <origin xyz="0.0 0.0 0.4409" rpy="0.0 0.0 0.8726648"/>
  </joint>

  <joint name="big_arm_joint_3" type="revolute">
    <parent link="big_arm_link_2"/>
    <child link="big_arm_link_3"/>
    <origin xyz="0.0 -0.177 0.1515" rpy="2.98023e-8 0.0  1.862645e-8"/>
    <axis xyz="0 1 0"/>
    <limit lower="-1.5708" upper="1.5708" velocity="3.1416" effort="100"/> <!-- MADE UP NUMBERS JUST FOR TESTING -->
  </joint>


  <joint name="big_arm_joint_4" type="revolute">
    <parent link="big_arm_link_3"/>
    <child link="big_arm_link_4"/>
    <origin xyz="0.17432 -0.1594 0.0" rpy="0.95993114 0.0 0.0"/>
    <axis xyz="1 0 0"/>
    <limit lower="-1.5708" upper="1.5708" velocity="3.1416" effort="100"/> <!-- MADE UP NUMBERS JUST FOR TESTING -->
  </joint>


  <joint name="big_arm_joint_5" type="revolute">
    <parent link="big_arm_link_4"/>
    <child link="big_arm_link_5"/>
    <origin xyz="0.3503 -0.004789 3.6578" rpy="1.3089968 0.0 0.0"/>
    <axis xyz="1 0 0"/>
    <limit lower="-1.5708" upper="1.5708" velocity="3.1416" effort="100"/> <!-- MADE UP NUMBERS JUST FOR TESTING -->
  </joint>


  <joint name="big_arm_joint_6" type="revolute">
    <parent link="big_arm_link_5"/>
    <child link="big_arm_link_6"/>
    <origin xyz="0.3503 0.004781 -3.6578" rpy="-0.5235989 0.0 0.0"/>
    <axis xyz="1 0 0"/>
    <limit lower="-1.5708" upper="1.5708" velocity="3.1416" effort="100"/> <!-- MADE UP NUMBERS JUST FOR TESTING -->
  </joint>


  <joint name="big_arm_joint_7" type="revolute">
    <parent link="big_arm_link_6"/>
    <child link="big_arm_link_7"/>
    <origin xyz="0.17429 -0.15194 0.0" rpy="0.0 0.0 0.0"/>
    <axis xyz="0 1 0"/>
    <limit lower="-1.5708" upper="1.5708" velocity="3.1416" effort="100"/> <!-- MADE UP NUMBERS JUST FOR TESTING -->
  </joint>


  <joint name="big_arm_joint_8" type="revolute">
    <parent link="big_arm_link_7"/>
    <child link="big_arm_link_8"/>
    <origin xyz="-0.004217 -0.1708 -0.181" rpy="0.0 0.0 0.0"/>
    <axis xyz="0 0 1"/>
    <limit lower="-1.5708" upper="1.5708" velocity="3.1416" effort="100"/> <!-- MADE UP NUMBERS JUST FOR TESTING -->
  </joint>



  <!-- LITTLE ARM -->
  <link name="little_arm_link_0"/>

  <link name="little_arm_link_1">
    <visual>
      <geometry>
        <mesh filename="package://gateway_description/meshes/little_arm/little_arm_link_1.dae" scale="1.0 1.0 1.0"/>
      </geometry>
    </visual>
    <collision> 
      <geometry>
        <mesh filename="package://gateway_description/meshes/little_arm/little_arm_link_1.dae" scale="1.0 1.0 1.0"/>
      </geometry>
    </collision>    
  </link>

  <link name="little_arm_link_2">
    <visual>
      <geometry>
        <mesh filename="package://gateway_description/meshes/little_arm/little_arm_link_2.dae" scale="1.0 1.0 1.0"/>
      </geometry>
    </visual>
    <collision> 
      <geometry>
        <mesh filename="package://gateway_description/meshes/little_arm/little_arm_link_2.dae" scale="1.0 1.0 1.0"/>
      </geometry>
    </collision>    
  </link>

  <link name="little_arm_link_3">
    <visual>
      <geometry>
        <mesh filename="package://gateway_description/meshes/little_arm/little_arm_link_3.dae" scale="1.0 1.0 1.0"/>
      </geometry>
    </visual>
    <collision> 
      <geometry>
        <mesh filename="package://gateway_description/meshes/little_arm/little_arm_link_3.dae" scale="1.0 1.0 1.0"/>
      </geometry>
    </collision>    
  </link>

  <link name="little_arm_link_4">
    <visual>
      <geometry>
        <mesh filename="package://gateway_description/meshes/little_arm/little_arm_link_4.dae" scale="1.0 1.0 1.0"/>
      </geometry>
    </visual>
    <collision> 
      <geometry>
        <mesh filename="package://gateway_description/meshes/little_arm/little_arm_link_4.dae" scale="1.0 1.0 1.0"/>
      </geometry>
    </collision>    
  </link>

  <link name="little_arm_link_5">
    <visual>
      <geometry>
        <mesh filename="package://gateway_description/meshes/little_arm/little_arm_link_5.dae" scale="1.0 1.0 1.0"/>
      </geometry>
    </visual>
    <collision> 
      <geometry>
        <mesh filename="package://gateway_description/meshes/little_arm/little_arm_link_5.dae" scale="1.0 1.0 1.0"/>
      </geometry>
    </collision>    
  </link>


  <link name="little_arm_link_6">
    <visual>
      <geometry>
        <mesh filename="package://gateway_description/meshes/little_arm/little_arm_link_6.dae" scale="1.0 1.0 1.0"/>
      </geometry>
    </visual>
    <collision> 
      <geometry>
        <mesh filename="package://gateway_description/meshes/little_arm/little_arm_link_6.dae" scale="1.0 1.0 1.0"/>
      </geometry>
    </collision>    
  </link>


  <link name="little_arm_link_7">
    <visual>
      <geometry>
        <mesh filename="package://gateway_description/meshes/little_arm/little_arm_link_7.dae" scale="1.0 1.0 1.0"/>
      </geometry>
    </visual>
    <collision> 
      <geometry>
        <mesh filename="package://gateway_description/meshes/little_arm/little_arm_link_7.dae" scale="1.0 1.0 1.0"/>
      </geometry>
    </collision>    
  </link>


  <link name="little_arm_link_8">
    <visual>
      <geometry>
        <mesh filename="package://gateway_description/meshes/little_arm/little_arm_link_8.dae" scale="1.0 1.0 1.0"/>
      </geometry>
    </visual>
    <collision> 
      <geometry>
        <mesh filename="package://gateway_description/meshes/little_arm/little_arm_link_8.dae" scale="1.0 1.0 1.0"/>
      </geometry>
    </collision>    
  </link>

  <link name="little_arm_link_9">
    <visual>
      <geometry>
        <mesh filename="package://gateway_description/meshes/little_arm/little_arm_link_9.dae" scale="1.0 1.0 1.0"/>
      </geometry>
    </visual>
    <collision> 
      <geometry>
        <mesh filename="package://gateway_description/meshes/little_arm/little_arm_link_9.dae" scale="1.0 1.0 1.0"/>
      </geometry>
    </collision>    
  </link>

  <joint name="little_arm_joint_0" type="fixed">
    <parent link="root"/>
    <child link="little_arm_link_0"/>
    <origin xyz="0.0 0.0 0.0" rpy="0.0 0.4363 -1.396"/>
  </joint>
  
  <joint name="little_arm_joint_1" type="fixed">
    <parent link="little_arm_link_0"/>
    <child link="little_arm_link_1"/>
    <origin xyz="13.984 -1.3352 -1.3367" rpy="2.3562 0.0 0.0"/>
  </joint>

  <joint name="little_arm_joint_2" type="revolute">
    <parent link="little_arm_link_1"/>
    <child link="little_arm_link_2"/>
    <axis xyz="0 0 1"/>
    <limit lower="-1.5708" upper="1.5708" velocity="3.1416" effort="100"/> <!-- MADE UP NUMBERS JUST FOR TESTING -->
    <origin xyz="0.44043 0.010424 0.29487" rpy="0.0 0.0 0.0"/>
  </joint>

  <joint name="little_arm_joint_3" type="revolute">
    <parent link="little_arm_link_2"/>
    <child link="little_arm_link_3"/>
    <origin xyz="0.38687 -0.008157 0.011094" rpy="0.0 0.0  0.0"/>
    <axis xyz="0 1 0"/>
    <limit lower="-1.5708" upper="1.5708" velocity="3.1416" effort="100"/> <!-- MADE UP NUMBERS JUST FOR TESTING -->
  </joint>


  <joint name="little_arm_joint_4" type="revolute">
    <parent link="little_arm_link_3"/>
    <child link="little_arm_link_4"/>
    <origin xyz="0.097745 0.0 -0.10467" rpy="0.0 0.0 1.5708"/>
    <axis xyz="1 0 0"/>
    <limit lower="-1.5708" upper="1.5708" velocity="3.1416" effort="100"/> <!-- MADE UP NUMBERS JUST FOR TESTING -->
  </joint>


  <joint name="little_arm_joint_5" type="revolute">
    <parent link="little_arm_link_4"/>
    <child link="little_arm_link_5"/>
    <origin xyz="-0.006176 -0.10467 -0.094197" rpy="0.0 0.0 0.0"/>
    <axis xyz="1 0 0"/>
    <limit lower="-1.5708" upper="1.5708" velocity="3.1416" effort="100"/> <!-- MADE UP NUMBERS JUST FOR TESTING -->
  </joint>


  <joint name="little_arm_joint_6" type="revolute">
    <parent link="little_arm_link_5"/>
    <child link="little_arm_link_6"/>
    <origin xyz="0.47551 -0.21354 0.008568" rpy="0.0 -0.6108 0.0"/>
    <axis xyz="1 0 0"/>
    <limit lower="-1.5708" upper="1.5708" velocity="3.1416" effort="100"/> <!-- MADE UP NUMBERS JUST FOR TESTING -->
  </joint>


  <joint name="little_arm_joint_7" type="revolute">
    <parent link="little_arm_link_6"/>
    <child link="little_arm_link_7"/>
    <origin xyz="0.47551 -0.21354 0.008567" rpy="0.0 0.4363324 0.0"/>
    <axis xyz="0 1 0"/>
    <limit lower="-1.5708" upper="1.5708" velocity="3.1416" effort="100"/> <!-- MADE UP NUMBERS JUST FOR TESTING -->
  </joint>


  <joint name="little_arm_joint_8" type="revolute">
    <parent link="little_arm_link_7"/>
    <child link="little_arm_link_8"/>
    <origin xyz="0.10062 -0.10467 -0.014366" rpy="0.0 0.0 0.0"/>
    <axis xyz="0 0 1"/>
    <limit lower="-1.5708" upper="1.5708" velocity="3.1416" effort="100"/> <!-- MADE UP NUMBERS JUST FOR TESTING -->
  </joint>

  <joint name="little_arm_joint_9" type="revolute">
    <parent link="little_arm_link_8"/>
    <child link="little_arm_link_9"/>
    <origin xyz="0.10467 0.000167 -0.10062" rpy="0.0 0.0 0.0"/>
    <axis xyz="0 0 1"/>
    <limit lower="-1.5708" upper="1.5708" velocity="3.1416" effort="100"/> <!-- MADE UP NUMBERS JUST FOR TESTING -->
  </joint>

</robot>
